Workbook

Sheet Raw_Data
A1: Employee ID | B1: Employee Name | C1: Department | D1: Designation | E1: Location | F1: Reporting Manager | G1: Date | H1: Attendance Status | I1: Login Time | J1: Logout Time | K1: Working Hours | L1: Tasks Assigned | M1: Tasks Completed | N1: Pending Tasks | O1: Daily Target | P1: Achievement % | Q1: Productivity % | R1: Overtime Hours | S1: Priority | T1: Case Status
A2: EMP001 | B2: Aarav Sharma | C2: Operations | D2: MIS Executive | E2: Kolkata | F2: Amit Roy | G2: 01-04-2026 | H2: Present | I2: 09:08 | J2: 16:55 | K2: 7.79 | L2: 25 | M2: 24 | N2: 1 | O2: 25 | P2: 96 | Q2: 96 | R2: 0 | S2: Medium | T2: In Progress
A3: EMP002 | B3: Priya Singh | C3: Operations | D3: Process Executive | E3: Kolkata | F3: Amit Roy | G3: 01-04-2026 | H3: Present | I3: 09:00 | J3: 16:25 | K3: 7.42 | L3: 25 | M3: 19 | N3: 6 | O3: 25 | P3: 76 | Q3: 76 | R3: 0 | S3: Medium | T3: Pending
A4: EMP003 | B4: Rahul Verma | C4: Operations | D4: Process Executive | E4: Kolkata | F4: Amit Roy | G4: 01-04-2026 | H4: Present | I4: 10:07 | J4: 18:23 | K4: 8.28 | L4: 22 | M4: 21 | N4: 1 | O4: 22 | P4: 95.5 | Q4: 95.5 | R4: 0.28 | S4: Low | T4: In Progress
A5: EMP004 | B5: Sneha Das | C5: Operations | D5: Senior Executive | E5: Kolkata | F5: Amit Roy | G5: 01-04-2026 | H5: Present | I5: 09:04 | J5: 16:47 | K5: 7.72 | L5: 33 | M5: 32 | N5: 1 | O5: 33 | P5: 97 | Q5: 97 | R5: 0 | S5: Low | T5: In Progress
A6: EMP005 | B6: Vikram Patel | C6: Operations | D6: Process Executive | E6: Kolkata | F6: Amit Roy | G6: 01-04-2026 | H6: Present | I6: 09:11 | J6: 17:50 | K6: 8.65 | L6: 26 | M6: 23 | N6: 3 | O6: 26 | P6: 88.5 | Q6: 88.5 | R6: 0.65 | S6: Critical | T6: In Progress
A7: EMP006 | B7: Ananya Gupta | C7: Finance | D7: Finance Executive | E7: Kolkata | F7: Neha Sen | G7: 01-04-2026 | H7: Present | I7: 09:20 | J7: 18:00 | K7: 8.68 | L7: 8 | M7: 8 | N7: 0 | O7: 8 | P7: 100 | Q7: 100 | R7: 0.68 | S7: Low | T7: Closed
A8: EMP007 | B8: Rohan Mehta | C8: Finance | D8: Accounts Executive | E8: Kolkata | F8: Neha Sen | G8: 01-04-2026 | H8: Present | I8: 09:01 | J8: 17:48 | K8: 8.79 | L8: 18 | M8: 18 | N8: 0 | O8: 18 | P8: 100 | Q8: 100 | R8: 0.79 | S8: Low | T8: Closed
A9: EMP008 | B9: Ishita Roy | C9: Finance | D9: Finance Executive | E9: Kolkata | F9: Neha Sen | G9: 01-04-2026 | H9: Present | I9: 10:08 | J9: 18:25 | K9: 8.29 | L9: 5 | M9: 5 | N9: 0 | O9: 5 | P9: 100 | Q9: 100 | R9: 0.29 | S9: Low | T9: Closed
A10: EMP009 | B10: Arjun Nair | C10: Sales | D10: Sales Executive | E10: Kolkata | F10: Sourav Das | G10: 01-04-2026 | H10: Present | I10: 09:06 | J10: 17:54 | K10: 8.81 | L10: 17 | M10: 12 | N10: 5 | O10: 17 | P10: 70.6 | Q10: 70.6 | R10: 0.81 | S10: Medium | T10: Pending
A11: EMP010 | B11: Meera Kapoor | C11: Sales | D11: Sales Executive | E11: Kolkata | F11: Sourav Das | G11: 01-04-2026 | H11: Present | I11: 09:05 | J11: 17:23 | K11: 8.31 | L11: 12 | M11: 9 | N11: 3 | O11: 12 | P11: 75 | Q11: 75 | R11: 0.31 | S11: High | T11: In Progress
A12: EMP011 | B12: Karan Malhotra | C12: Sales | D12: Senior Executive | E12: Kolkata | F12: Sourav Das | G12: 01-04-2026 | H12: Present | I12: 09:10 | J12: 18:23 | K12: 9.22 | L12: 20 | M12: 14 | N12: 6 | O12: 20 | P12: 70 | Q12: 70 | R12: 1.22 | S12: Low | T12: Pending
A13: EMP012 | B13: Tanya Bose | C13: HR | D13: HR Executive | E13: Kolkata | F13: Ritu Ghosh | G13: 01-04-2026 | H13: Present | I13: 09:18 | J13: 18:36 | K13: 9.3 | L13: 8 | M13: 6 | N13: 2 | O13: 8 | P13: 75 | Q13: 75 | R13: 1.3 | S13: Medium | T13: In Progress
... A46: EMP005 | B46: Vikram Patel | C46: Operations | D46: Process Executive | E46: Kolkata | F46: Amit Roy | G46: 03-04-2026 | H46: Present | I46: 09:02 | J46: 17:45 | K46: 8.72 | L46: 24 | M46: 19 | N46: 5 | O46: 24 | P46: 79.2 | Q46: 79.2 | R46: 0.72 | S46: Low | T46: Pending
A47: EMP006 | B47: Ananya Gupta | C47: Finance | D47: Finance Executive | E47: Kolkata | F47: Neha Sen | G47: 03-04-2026 | H47: Leave | K47: 0 | L47: 0 | M47: 0 | N47: 0 | O47: 0 | P47: 0 | Q47: 0 | R47: 0 | S47: Low | T47: Closed
A48: EMP007 | B48: Rohan Mehta | C48: Finance | D48: Accounts Executive | E48: Kolkata | F48: Neha Sen | G48: 03-04-2026 | H48: Present | I48: 10:17 | J48: 19:10 | K48: 8.89 | L48: 14 | M48: 12 | N48: 2 | O48: 14 | P48: 85.7 | Q48: 85.7 | R48: 0.89 | S48: Low | T48: In Progress
A49: EMP008 | B49: Ishita Roy | C49: Finance | D49: Finance Executive | E49: Kolkata | F49: Neha Sen | G49: 03-04-2026 | H49: Late | I49: 11:28 | J49: 19:01 | K49: 7.56 | L49: 20 | M49: 18 | N49: 2 | O49: 20 | P49: 90 | Q49: 90 | R49: 0 | S49: Medium | T49: In Progress
A50: EMP009 | B50: Arjun Nair | C50: Sales | D50: Sales Executive | E50: Kolkata | F50: Sourav Das | G50: 03-04-2026 | H50: Present | I50: 09:01 | J50: 18:22 | K50: 9.36 | L50: 21 | M50: 16 | N50: 5 | O50: 21 | P50: 76.2 | Q50: 76.2 | R50: 1.36 | S50: Low | T50: Pending
A51: EMP010 | B51: Meera Kapoor | C51: Sales | D51: Sales Executive | E51: Kolkata | F51: Sourav Das | G51: 03-04-2026 | H51: Present | I51: 10:19 | J51: 19:19 | K51: 9 | L51: 23 | M51: 17 | N51: 6 | O51: 23 | P51: 73.9 | Q51: 73.9 | R51: 1 | S51: Medium | T51: Pending
A52: EMP011 | B52: Karan Malhotra | C52: Sales | D52: Senior Executive | E52: Kolkata | F52: Sourav Das | G52: 03-04-2026 | H52: Present | I52: 10:00 | J52: 17:37 | K52: 7.63 | L52: 18 | M52: 18 | N52: 0 | O52: 18 | P52: 100 | Q52: 100 | R52: 0 | S52: Low | T52: Closed
A53: EMP012 | B53: Tanya Bose | C53: HR | D53: HR Executive | E53: Kolkata | F53: Ritu Ghosh | G53: 03-04-2026 | H53: Present | I53: 10:07 | J53: 17:57 | K53: 7.84 | L53: 12 | M53: 12 | N53: 0 | O53: 12 | P53: 100 | Q53: 100 | R53: 0 | S53: Low | T53: Closed
A54: EMP013 | B54: Aditya Jain | C54: Customer Support | D54: Support Executive | E54: Kolkata | F54: Ritu Ghosh | G54: 03-04-2026 | H54: Present | I54: 09:06 | J54: 18:15 | K54: 9.16 | L54: 25 | M54: 21 | N54: 4 | O54: 25 | P54: 84 | Q54: 84 | R54: 1.16 | S54: Low | T54: Pending
A55: EMP014 | B55: Neha Agarwal | C55: Customer Support | D55: Support Executive | E55: Kolkata | F55: Ritu Ghosh | G55: 03-04-2026 | H55: Present | I55: 09:07 | J55: 16:22 | K55: 7.26 | L55: 29 | M55: 29 | N55: 0 | O55: 29 | P55: 100 | Q55: 100 | R55: 0 | S55: Low | T55: Closed
A56: EMP015 | B56: Siddharth Roy | C56: Customer Support | D56: Senior Executive | E56: Kolkata | F56: Ritu Ghosh | G56: 03-04-2026 | H56: Leave | K56: 0 | L56: 0 | M56: 0 | N56: 0 | O56: 0 | P56: 0 | Q56: 0 | R56: 0 | S56: Low | T56: Closed
A57: EMP016 | B57: Pooja Saha | C57: Operations | D57: Process Executive | E57: Durgapur | F57: Amit Roy | G57: 03-04-2026 | H57: Present | I57: 10:17 | J57: 18:16 | K57: 7.99 | L57: 28 | M57: 19 | N57: 9 | O57: 28 | P57: 67.9 | Q57: 67.9 | R57: 0 | S57: High | T57: Backlog
A58: EMP017 | B58: Abhishek Paul | C58: Operations | D58: Process Executive | E58: Durgapur | F58: Amit Roy | G58: 03-04-2026 | H58: Present | I58: 09:01 | J58: 16:28 | K58: 7.46 | L58: 16 | M58: 13 | N58: 3 | O58: 16 | P58: 81.2 | Q58: 81.2 | R58: 0 | S58: Medium | T58: In Progress
A59: EMP018 | B59: Nandini Ghosh | C59: Finance | D59: Finance Executive | E59: Durgapur | F59: Neha Sen | G59: 03-04-2026 | H59: Present | I59: 10:18 | J59: 17:57 | K59: 7.66 | L59: 19 | M59: 13 | N59: 6 | O59: 19 | P59: 68.4 | Q59: 68.4 | R59: 0 | S59: Medium | T59: Pending
A60: EMP019 | B60: Manish Kumar | C60: Sales | D60: Sales Executive | E60: Durgapur | F60: Sourav Das | G60: 03-04-2026 | H60: Present | I60: 09:11 | J60: 17:25 | K60: 8.24 | L60: 30 | M60: 28 | N60: 2 | O60: 30 | P60: 93.3 | Q60: 93.3 | R60: 0.24 | S60: Medium | T60: In Progress
A61: EMP020 | B61: Riya Chatterjee | C61: Customer Support | D61: Support Executive | E61: Durgapur | F61: Ritu Ghosh | G61: 03-04-2026 | H61: Present | I61: 09:16 | J61: 17:12 | K61: 7.94 | L61: 24 | M61: 20 | N61: 4 | O61: 24 | P61: 83.3 | Q61: 83.3 | R61: 0 | S61: Medium | T61: Pending
A62: EMP001 | B62: Aarav Sharma | C62: Operations | D62: MIS Executive | E62: Kolkata | F62: Amit Roy | G62: 04-04-2026 | H62: Present | I62: 09:06 | J62: 17:18 | K62: 8.21 | L62: 30 | M62: 30 | N62: 0 | O62: 30 | P62: 100 | Q62: 100 | R62: 0.21 | S62: Low | T62: Closed
A63: EMP002 | B63: Priya Singh | C63: Operations | D63: Process Executive | E63: Kolkata | F63: Amit Roy | G63: 04-04-2026 | H63: Present | I63: 09:12 | J63: 17:43 | K63: 8.52 | L63: 21 | M63: 14 | N63: 7 | O63: 21 | P63: 66.7 | Q63: 66.7 | R63: 0.52 | S63: Low | T63: Pending
A64: EMP003 | B64: Rahul Verma | C64: Operations | D64: Process Executive | E64: Kolkata | F64: Amit Roy | G64: 04-04-2026 | H64: Present | I64: 09:14 | J64: 17:29 | K64: 8.26 | L64: 21 | M64: 21 | N64: 0 | O64: 21 | P64: 100 | Q64: 100 | R64: 0.26 | S64: Low | T64: Closed
A65: EMP004 | B65: Sneha Das | C65: Operations | D65: Senior Executive | E65: Kolkata | F65: Amit Roy | G65: 04-04-2026 | H65: Leave | K65: 0 | L65: 0 | M65: 0 | N65: 0 | O65: 0 | P65: 0 | Q65: 0 | R65: 0 | S65: Low | T65: Closed
A66: EMP005 | B66: Vikram Patel | C66: Operations | D66: Process Executive | E66: Kolkata | F66: Amit Roy | G66: 04-04-2026 | H66: Present | I66: 09:09 | J66: 17:35 | K66: 8.44 | L66: 18 | M66: 16 | N66: 2 | O66: 18 | P66: 88.9 | Q66: 88.9 | R66: 0.44 | S66: Low | T66: In Progress
A67: EMP006 | B67: Ananya Gupta | C67: Finance | D67: Finance Executive | E67: Kolkata | F67: Neha Sen | G67: 04-04-2026 | H67: Present | I67: 09:09 | J67: 16:53 | K67: 7.74 | L67: 16 | M67: 12 | N67: 4 | O67: 16 | P67: 75 | Q67: 75 | R67: 0 | S67: Medium | T67: Pending
A68: EMP007 | B68: Rohan Mehta | C68: Finance | D68: Accounts Executive | E68: Kolkata | F68: Neha Sen | G68: 04-04-2026 | H68: Present | I68: 09:14 | J68: 17:25 | K68: 8.19 | L68: 17 | M68: 15 | N68: 2 | O68: 17 | P68: 88.2 | Q68: 88.2 | R68: 0.19 | S68: Low | T68: In Progress
A69: EMP008 | B69: Ishita Roy | C69: Finance | D69: Finance Executive | E69: Kolkata | F69: Neha Sen | G69: 04-04-2026 | H69: Present | I69: 10:12 | J69: 17:59 | K69: 7.79 | L69: 15 | M69: 14 | N69: 1 | O69: 15 | P69: 93.3 | Q69: 93.3 | R69: 0 | S69: Medium | T69: In Progress
A70: EMP009 | B70: Arjun Nair | C70: Sales | D70: Sales Executive | E70: Kolkata | F70: Sourav Das | G70: 04-04-2026 | H70: Present | I70: 10:07 | J70: 17:44 | K70: 7.62 | L70: 19 | M70: 19 | N70: 0 | O70: 19 | P70: 100 | Q70: 100 | R70: 0 | S70: Low | T70: Closed
A71: EMP010 | B71: Meera Kapoor | C71: Sales | D71: Sales Executive | E71: Kolkata | F71: Sourav Das | G71: 04-04-2026 | H71: Present | I71: 09:17 | J71: 17:05 | K71: 7.8 | L71: 23 | M71: 23 | N71: 0 | O71: 23 | P71: 100 | Q71: 100 | R71: 0 | S71: Low | T71: Closed
A72: EMP011 | B72: Karan Malhotra | C72: Sales | D72: Senior Executive | E72: Kolkata | F72: Sourav Das | G72: 04-04-2026 | H72: Present | I72: 09:14 | J72: 17:54 | K72: 8.67 | L72: 15 | M72: 14 | N72: 1 | O72: 15 | P72: 93.3 | Q72: 93.3 | R72: 0.67 | S72: Medium | T72: In Progress
...

Sheet Checking_and_Manipulation
A1: MIS Data Validation & Manipulation Log
A2: Employee Productivity Dataset | Source: Raw_Data sheet (2,880 records, 20 employees, Apr–Sep 2026)
A4: A. STRUCTURAL DATA QUALITY CHECKS
A5: Check | D5: Formula Used | G5: Result | H5: Status
A6: Blank Employee IDs | D6: =COUNTBLANK(Raw_Data!A2:A2881) | G6: =COUNTBLANK(Raw_Data!A2:A2881) -> 0 | H6: =IF(G6=0,"OK","REVIEW") -> OK
A7: Blank Employee Names | D7: =COUNTBLANK(Raw_Data!B2:B2881) | G7: =COUNTBLANK(Raw_Data!B2:B2881) -> 0 | H7: =IF(G7=0,"OK","REVIEW") -> OK
A8: Blank Departments | D8: =COUNTBLANK(Raw_Data!C2:C2881) | G8: =COUNTBLANK(Raw_Data!C2:C2881) -> 0 | H8: =IF(G8=0,"OK","REVIEW") -> OK
A9: Blank Dates | D9: =COUNTBLANK(Raw_Data!G2:G2881) | G9: =COUNTBLANK(Raw_Data!G2:G2881) -> 0 | H9: =IF(G9=0,"OK","REVIEW") -> OK
A10: Duplicate Employee ID + Date combinations | D10: =SUMPRODUCT((COUNTIFS(Raw_Data!A2:A2881,Raw_Data!A2:A2881,Raw_Data!G2:G2881,Raw_Data!G2:G2881)>1)*1) | G10: =SUMPRODUCT((COUNTIFS(Raw_Data!A2:A2881,Raw_Data!A2:A2881,Raw_Data!G2:G2881,Raw_Data!G2:G2881)>1)*1) -> 0 | H10: =IF(G10=0,"OK","REVIEW") -> OK
A11: Negative Working Hours | D11: =COUNTIF(Raw_Data!K2:K2881,"<0") | G11: =COUNTIF(Raw_Data!K2:K2881,"<0") -> 0 | H11: =IF(G11=0,"OK","REVIEW") -> OK
A12: Negative Pending Tasks | D12: =COUNTIF(Raw_Data!N2:N2881,"<0") | G12: =COUNTIF(Raw_Data!N2:N2881,"<0") -> 0 | H12: =IF(G12=0,"OK","REVIEW") -> OK
A13: Tasks Completed > Tasks Assigned (impossible) | D13: =SUMPRODUCT((Raw_Data!M2:M2881>Raw_Data!L2:L2881)*1) | G13: =SUMPRODUCT((Raw_Data!M2:M2881>Raw_Data!L2:L2881)*1) -> 0 | H13: =IF(G13=0,"OK","REVIEW") -> OK
A14: Achievement % outside 0–100 range | D14: =SUMPRODUCT(((Raw_Data!P2:P2881<0)+(Raw_Data!P2:P2881>100))*1) | G14: =SUMPRODUCT(((Raw_Data!P2:P2881<0)+(Raw_Data!P2:P2881>100))*1) -> 0 | H14: =IF(G14=0,"OK","REVIEW") -> OK
A15: Working Hours outside 0–12 range | D15: =SUMPRODUCT(((Raw_Data!K2:K2881<0)+(Raw_Data!K2:K2881>12))*1) | G15: =SUMPRODUCT(((Raw_Data!K2:K2881<0)+(Raw_Data!K2:K2881>12))*1) -> 0 | H15: =IF(G15=0,"OK","REVIEW") -> OK
A16: Date column stored as TEXT, not numeric Date | D16: =SUMPRODUCT((ISNUMBER(Raw_Data!G2:G2881))*1) | G16: =SUMPRODUCT((ISNUMBER(Raw_Data!G2:G2881))*1) -> 0 | H16: =IF(G16=0,"CONFIRMED TEXT - FIX APPLIED","0 rows - already numeric") -> CONFIRMED TEXT - FIX APPLIED
A17: Login/Logout Time blanks (expected only for Absent/Leave) | D17: =COUNTBLANK(Raw_Data!I2:I2881) | G17: =COUNTBLANK(Raw_Data!I2:I2881) -> 92 | H17: =IF(G17=COUNTIF(Raw_Data!H2:H2881,"Absent")+COUNTIF(Raw_Data!H2:H2881,"Leave"),"EXPECTED (matches Absent+Leave)","REVIEW") -> EXPECTED (matches Absent+Leave)
A19: B. MANIPULATIONS APPLIED (Raw_Data → Cleaned_Data)
A20: # | B20: Column | C20: Issue Found | E20: Transformation Formula (used in Cleaned_Data) | H20: Why
A21: 1 | B21: Date | C21: Stored as text (DD-MM-YYYY); unusable for PivotTables/time filters | E21: DATE(VALUE(RIGHT(txt,4)), VALUE(MID(txt,4,2)), VALUE(LEFT(txt,2))) | H21: Locale-safe date rebuild; enables trend charts, month grouping
A22: 2 | B22: Login Time / Logout Time | C22: Stored as text; blank for Absent/Leave (92 rows — expected, not an error) | E22: IF(txt="","",TIMEVALUE(txt)) | H22: Real time type allows shift/lateness analysis; blanks preserved intentionally
A23: 3 | B23: Pending Tasks | C23: Recomputed independently to verify against source (0 mismatches found) | E23: Tasks_Assigned minus Tasks_Completed | H23: Cross-check formula guarantees consistency, not just copied
A24: 4 | B24: Achievement % | C24: Recomputed independently from source Tasks (0 mismatches found) | E24: IFERROR(Tasks_Completed / Tasks_Assigned * 100, 0) | H24: Formula-driven, not hardcoded — recalculates if source changes
A25: 5 | B25: Achievement % vs Productivity % | C25: Found to be 100% identical duplicate columns in source data | E25: Both retained in Cleaned_Data; flagged here for transparency | H25: MIS best practice: never silently drop a source column
A26: 6 | B26: Helper columns added | C26: None in source | E26: Month, Day of Week (for pivoting) | H26: Needed for the monthly trend charts on Tables_and_Charts
A28: C. BEFORE / AFTER SAMPLE (first 8 records)
A29: Employee ID | B29: Date (Raw - TEXT) | C29: Date (Cleaned - DATE) | D29: Login (Raw - TEXT) | E29: Login (Cleaned - TIME) | F29: Logout (Raw - TEXT) | G29: Logout (Cleaned - TIME) | H29: Attendance
A30: =Raw_Data!A2 -> EMP001 | B30: =Raw_Data!G2 -> 01-04-2026 | C30: =DATE(VALUE(RIGHT(Raw_Data!G2,4)),VALUE(MID(Raw_Data!G2,4,2)),VALUE(LEFT(Raw_Data!G2,2))) -> 46113 | D30: =Raw_Data!I2 -> 09:08 | E30: =IF(Raw_Data!I2="","",TIMEVALUE(Raw_Data!I2)) -> 0.38055556 | F30: =Raw_Data!J2 -> 16:55 | G30: =IF(Raw_Data!J2="","",TIMEVALUE(Raw_Data!J2)) -> 0.70486111 | H30: =Raw_Data!H2 -> Present
A31: =Raw_Data!A3 -> EMP002 | B31: =Raw_Data!G3 -> 01-04-2026 | C31: =DATE(VALUE(RIGHT(Raw_Data!G3,4)),VALUE(MID(Raw_Data!G3,4,2)),VALUE(LEFT(Raw_Data!G3,2))) -> 46113 | D31: =Raw_Data!I3 -> 09:00 | E31: =IF(Raw_Data!I3="","",TIMEVALUE(Raw_Data!I3)) -> 0.375 | F31: =Raw_Data!J3 -> 16:25 | G31: =IF(Raw_Data!J3="","",TIMEVALUE(Raw_Data!J3)) -> 0.68402778 | H31: =Raw_Data!H3 -> Present
A32: =Raw_Data!A4 -> EMP003 | B32: =Raw_Data!G4 -> 01-04-2026 | C32: =DATE(VALUE(RIGHT(Raw_Data!G4,4)),VALUE(MID(Raw_Data!G4,4,2)),VALUE(LEFT(Raw_Data!G4,2))) -> 46113 | D32: =Raw_Data!I4 -> 10:07 | E32: =IF(Raw_Data!I4="","",TIMEVALUE(Raw_Data!I4)) -> 0.42152778 | F32: =Raw_Data!J4 -> 18:23 | G32: =IF(Raw_Data!J4="","",TIMEVALUE(Raw_Data!J4)) -> 0.76597222 | H32: =Raw_Data!H4 -> Present
A33: =Raw_Data!A5 -> EMP004 | B33: =Raw_Data!G5 -> 01-04-2026 | C33: =DATE(VALUE(RIGHT(Raw_Data!G5,4)),VALUE(MID(Raw_Data!G5,4,2)),VALUE(LEFT(Raw_Data!G5,2))) -> 46113 | D33: =Raw_Data!I5 -> 09:04 | E33: =IF(Raw_Data!I5="","",TIMEVALUE(Raw_Data!I5)) -> 0.37777778 | F33: =Raw_Data!J5 -> 16:47 | G33: =IF(Raw_Data!J5="","",TIMEVALUE(Raw_Data!J5)) -> 0.69930556 | H33: =Raw_Data!H5 -> Present
A34: =Raw_Data!A6 -> EMP005 | B34: =Raw_Data!G6 -> 01-04-2026 | C34: =DATE(VALUE(RIGHT(Raw_Data!G6,4)),VALUE(MID(Raw_Data!G6,4,2)),VALUE(LEFT(Raw_Data!G6,2))) -> 46113 | D34: =Raw_Data!I6 -> 09:11 | E34: =IF(Raw_Data!I6="","",TIMEVALUE(Raw_Data!I6)) -> 0.38263889 | F34: =Raw_Data!J6 -> 17:50 | G34: =IF(Raw_Data!J6="","",TIMEVALUE(Raw_Data!J6)) -> 0.74305556 | H34: =Raw_Data!H6 -> Present
A35: =Raw_Data!A7 -> EMP006 | B35: =Raw_Data!G7 -> 01-04-2026 | C35: =DATE(VALUE(RIGHT(Raw_Data!G7,4)),VALUE(MID(Raw_Data!G7,4,2)),VALUE(LEFT(Raw_Data!G7,2))) -> 46113 | D35: =Raw_Data!I7 -> 09:20 | E35: =IF(Raw_Data!I7="","",TIMEVALUE(Raw_Data!I7)) -> 0.38888889 | F35: =Raw_Data!J7 -> 18:00 | G35: =IF(Raw_Data!J7="","",TIMEVALUE(Raw_Data!J7)) -> 0.75 | H35: =Raw_Data!H7 -> Present
A36: =Raw_Data!A8 -> EMP007 | B36: =Raw_Data!G8 -> 01-04-2026 | C36: =DATE(VALUE(RIGHT(Raw_Data!G8,4)),VALUE(MID(Raw_Data!G8,4,2)),VALUE(LEFT(Raw_Data!G8,2))) -> 46113 | D36: =Raw_Data!I8 -> 09:01 | E36: =IF(Raw_Data!I8="","",TIMEVALUE(Raw_Data!I8)) -> 0.37569444 | F36: =Raw_Data!J8 -> 17:48 | G36: =IF(Raw_Data!J8="","",TIMEVALUE(Raw_Data!J8)) -> 0.74166667 | H36: =Raw_Data!H8 -> Present
A37: =Raw_Data!A9 -> EMP008 | B37: =Raw_Data!G9 -> 01-04-2026 | C37: =DATE(VALUE(RIGHT(Raw_Data!G9,4)),VALUE(MID(Raw_Data!G9,4,2)),VALUE(LEFT(Raw_Data!G9,2))) -> 46113 | D37: =Raw_Data!I9 -> 10:08 | E37: =IF(Raw_Data!I9="","",TIMEVALUE(Raw_Data!I9)) -> 0.42222222 | F37: =Raw_Data!J9 -> 18:25 | G37: =IF(Raw_Data!J9="","",TIMEVALUE(Raw_Data!J9)) -> 0.76736111 | H37: =Raw_Data!H9 -> Present

Sheet Cleaned_Data
A1: Employee ID | B1: Employee Name | C1: Department | D1: Designation | E1: Location | F1: Reporting Manager | G1: Date | H1: Month | I1: Day of Week | J1: Attendance Status | K1: Login Time | L1: Logout Time | M1: Working Hours | N1: Tasks Assigned | O1: Tasks Completed | P1: Pending Tasks | Q1: Daily Target | R1: Achievement % | S1: Productivity % | T1: Overtime Hours | U1: Priority | V1: Case Status
A2: =Raw_Data!A2 -> EMP001 | B2: =Raw_Data!B2 -> Aarav Sharma | C2: =Raw_Data!C2 -> Operations | D2: =Raw_Data!D2 -> MIS Executive | E2: =Raw_Data!E2 -> Kolkata | F2: =Raw_Data!F2 -> Amit Roy | G2: =DATE(VALUE(RIGHT(Raw_Data!G2,4)),VALUE(MID(Raw_Data!G2,4,2)),VALUE(LEFT(Raw_Data!G2,2))) -> 46113 | H2: =TEXT(G2,"mmm-yyyy") -> Apr-2026 | I2: =TEXT(G2,"ddd") -> Wed | J2: =Raw_Data!H2 -> Present | K2: =IF(Raw_Data!I2="","",TIMEVALUE(Raw_Data!I2)) -> 0.38055556 | L2: =IF(Raw_Data!J2="","",TIMEVALUE(Raw_Data!J2)) -> 0.70486111 | M2: =Raw_Data!K2 -> 7.79 | N2: =Raw_Data!L2 -> 25 | O2: =Raw_Data!M2 -> 24 | P2: =N2-O2 -> 1 | Q2: =Raw_Data!O2 -> 25 | R2: =IFERROR(O2/N2*100,0) -> 96 | S2: =Raw_Data!Q2 -> 96 | T2: =Raw_Data!R2 -> 0 | U2: =Raw_Data!S2 -> Medium | V2: =Raw_Data!T2 -> In Progress
A3: =Raw_Data!A3 -> EMP002 | B3: =Raw_Data!B3 -> Priya Singh | C3: =Raw_Data!C3 -> Operations | D3: =Raw_Data!D3 -> Process Executive | E3: =Raw_Data!E3 -> Kolkata | F3: =Raw_Data!F3 -> Amit Roy | G3: =DATE(VALUE(RIGHT(Raw_Data!G3,4)),VALUE(MID(Raw_Data!G3,4,2)),VALUE(LEFT(Raw_Data!G3,2))) -> 46113 | H3: =TEXT(G3,"mmm-yyyy") -> Apr-2026 | I3: =TEXT(G3,"ddd") -> Wed | J3: =Raw_Data!H3 -> Present | K3: =IF(Raw_Data!I3="","",TIMEVALUE(Raw_Data!I3)) -> 0.375 | L3: =IF(Raw_Data!J3="","",TIMEVALUE(Raw_Data!J3)) -> 0.68402778 | M3: =Raw_Data!K3 -> 7.42 | N3: =Raw_Data!L3 -> 25 | O3: =Raw_Data!M3 -> 19 | P3: =N3-O3 -> 6 | Q3: =Raw_Data!O3 -> 25 | R3: =IFERROR(O3/N3*100,0) -> 76 | S3: =Raw_Data!Q3 -> 76 | T3: =Raw_Data!R3 -> 0 | U3: =Raw_Data!S3 -> Medium | V3: =Raw_Data!T3 -> Pending
A4: =Raw_Data!A4 -> EMP003 | B4: =Raw_Data!B4 -> Rahul Verma | C4: =Raw_Data!C4 -> Operations | D4: =Raw_Data!D4 -> Process Executive | E4: =Raw_Data!E4 -> Kolkata | F4: =Raw_Data!F4 -> Amit Roy | G4: =DATE(VALUE(RIGHT(Raw_Data!G4,4)),VALUE(MID(Raw_Data!G4,4,2)),VALUE(LEFT(Raw_Data!G4,2))) -> 46113 | H4: =TEXT(G4,"mmm-yyyy") -> Apr-2026 | I4: =TEXT(G4,"ddd") -> Wed | J4: =Raw_Data!H4 -> Present | K4: =IF(Raw_Data!I4="","",TIMEVALUE(Raw_Data!I4)) -> 0.42152778 | L4: =IF(Raw_Data!J4="","",TIMEVALUE(Raw_Data!J4)) -> 0.76597222 | M4: =Raw_Data!K4 -> 8.28 | N4: =Raw_Data!L4 -> 22 | O4: =Raw_Data!M4 -> 21 | P4: =N4-O4 -> 1 | Q4: =Raw_Data!O4 -> 22 | R4: =IFERROR(O4/N4*100,0) -> 95.454545 | S4: =Raw_Data!Q4 -> 95.5 | T4: =Raw_Data!R4 -> 0.28 | U4: =Raw_Data!S4 -> Low | V4: =Raw_Data!T4 -> In Progress
A5: =Raw_Data!A5 -> EMP004 | B5: =Raw_Data!B5 -> Sneha Das | C5: =Raw_Data!C5 -> Operations | D5: =Raw_Data!D5 -> Senior Executive | E5: =Raw_Data!E5 -> Kolkata | F5: =Raw_Data!F5 -> Amit Roy | G5: =DATE(VALUE(RIGHT(Raw_Data!G5,4)),VALUE(MID(Raw_Data!G5,4,2)),VALUE(LEFT(Raw_Data!G5,2))) -> 46113 | H5: =TEXT(G5,"mmm-yyyy") -> Apr-2026 | I5: =TEXT(G5,"ddd") -> Wed | J5: =Raw_Data!H5 -> Present | K5: =IF(Raw_Data!I5="","",TIMEVALUE(Raw_Data!I5)) -> 0.37777778 | L5: =IF(Raw_Data!J5="","",TIMEVALUE(Raw_Data!J5)) -> 0.69930556 | M5: =Raw_Data!K5 -> 7.72 | N5: =Raw_Data!L5 -> 33 | O5: =Raw_Data!M5 -> 32 | P5: =N5-O5 -> 1 | Q5: =Raw_Data!O5 -> 33 | R5: =IFERROR(O5/N5*100,0) -> 96.969697 | S5: =Raw_Data!Q5 -> 97 | T5: =Raw_Data!R5 -> 0 | U5: =Raw_Data!S5 -> Low | V5: =Raw_Data!T5 -> In Progress
A6: =Raw_Data!A6 -> EMP005 | B6: =Raw_Data!B6 -> Vikram Patel | C6: =Raw_Data!C6 -> Operations | D6: =Raw_Data!D6 -> Process Executive | E6: =Raw_Data!E6 -> Kolkata | F6: =Raw_Data!F6 -> Amit Roy | G6: =DATE(VALUE(RIGHT(Raw_Data!G6,4)),VALUE(MID(Raw_Data!G6,4,2)),VALUE(LEFT(Raw_Data!G6,2))) -> 46113 | H6: =TEXT(G6,"mmm-yyyy") -> Apr-2026 | I6: =TEXT(G6,"ddd") -> Wed | J6: =Raw_Data!H6 -> Present | K6: =IF(Raw_Data!I6="","",TIMEVALUE(Raw_Data!I6)) -> 0.38263889 | L6: =IF(Raw_Data!J6="","",TIMEVALUE(Raw_Data!J6)) -> 0.74305556 | M6: =Raw_Data!K6 -> 8.65 | N6: =Raw_Data!L6 -> 26 | O6: =Raw_Data!M6 -> 23 | P6: =N6-O6 -> 3 | Q6: =Raw_Data!O6 -> 26 | R6: =IFERROR(O6/N6*100,0) -> 88.461538 | S6: =Raw_Data!Q6 -> 88.5 | T6: =Raw_Data!R6 -> 0.65 | U6: =Raw_Data!S6 -> Critical | V6: =Raw_Data!T6 -> In Progress
A7: =Raw_Data!A7 -> EMP006 | B7: =Raw_Data!B7 -> Ananya Gupta | C7: =Raw_Data!C7 -> Finance | D7: =Raw_Data!D7 -> Finance Executive | E7: =Raw_Data!E7 -> Kolkata | F7: =Raw_Data!F7 -> Neha Sen | G7: =DATE(VALUE(RIGHT(Raw_Data!G7,4)),VALUE(MID(Raw_Data!G7,4,2)),VALUE(LEFT(Raw_Data!G7,2))) -> 46113 | H7: =TEXT(G7,"mmm-yyyy") -> Apr-2026 | I7: =TEXT(G7,"ddd") -> Wed | J7: =Raw_Data!H7 -> Present | K7: =IF(Raw_Data!I7="","",TIMEVALUE(Raw_Data!I7)) -> 0.38888889 | L7: =IF(Raw_Data!J7="","",TIMEVALUE(Raw_Data!J7)) -> 0.75 | M7: =Raw_Data!K7 -> 8.68 | N7: =Raw_Data!L7 -> 8 | O7: =Raw_Data!M7 -> 8 | P7: =N7-O7 -> 0 | Q7: =Raw_Data!O7 -> 8 | R7: =IFERROR(O7/N7*100,0) -> 100 | S7: =Raw_Data!Q7 -> 100 | T7: =Raw_Data!R7 -> 0.68 | U7: =Raw_Data!S7 -> Low | V7: =Raw_Data!T7 -> Closed
A8: =Raw_Data!A8 -> EMP007 | B8: =Raw_Data!B8 -> Rohan Mehta | C8: =Raw_Data!C8 -> Finance | D8: =Raw_Data!D8 -> Accounts Executive | E8: =Raw_Data!E8 -> Kolkata | F8: =Raw_Data!F8 -> Neha Sen | G8: =DATE(VALUE(RIGHT(Raw_Data!G8,4)),VALUE(MID(Raw_Data!G8,4,2)),VALUE(LEFT(Raw_Data!G8,2))) -> 46113 | H8: =TEXT(G8,"mmm-yyyy") -> Apr-2026 | I8: =TEXT(G8,"ddd") -> Wed | J8: =Raw_Data!H8 -> Present | K8: =IF(Raw_Data!I8="","",TIMEVALUE(Raw_Data!I8)) -> 0.37569444 | L8: =IF(Raw_Data!J8="","",TIMEVALUE(Raw_Data!J8)) -> 0.74166667 | M8: =Raw_Data!K8 -> 8.79 | N8: =Raw_Data!L8 -> 18 | O8: =Raw_Data!M8 -> 18 | P8: =N8-O8 -> 0 | Q8: =Raw_Data!O8 -> 18 | R8: =IFERROR(O8/N8*100,0) -> 100 | S8: =Raw_Data!Q8 -> 100 | T8: =Raw_Data!R8 -> 0.79 | U8: =Raw_Data!S8 -> Low | V8: =Raw_Data!T8 -> Closed
A9: =Raw_Data!A9 -> EMP008 | B9: =Raw_Data!B9 -> Ishita Roy | C9: =Raw_Data!C9 -> Finance | D9: =Raw_Data!D9 -> Finance Executive | E9: =Raw_Data!E9 -> Kolkata | F9: =Raw_Data!F9 -> Neha Sen | G9: =DATE(VALUE(RIGHT(Raw_Data!G9,4)),VALUE(MID(Raw_Data!G9,4,2)),VALUE(LEFT(Raw_Data!G9,2))) -> 46113 | H9: =TEXT(G9,"mmm-yyyy") -> Apr-2026 | I9: =TEXT(G9,"ddd") -> Wed | J9: =Raw_Data!H9 -> Present | K9: =IF(Raw_Data!I9="","",TIMEVALUE(Raw_Data!I9)) -> 0.42222222 | L9: =IF(Raw_Data!J9="","",TIMEVALUE(Raw_Data!J9)) -> 0.76736111 | M9: =Raw_Data!K9 -> 8.29 | N9: =Raw_Data!L9 -> 5 | O9: =Raw_Data!M9 -> 5 | P9: =N9-O9 -> 0 | Q9: =Raw_Data!O9 -> 5 | R9: =IFERROR(O9/N9*100,0) -> 100 | S9: =Raw_Data!Q9 -> 100 | T9: =Raw_Data!R9 -> 0.29 | U9: =Raw_Data!S9 -> Low | V9: =Raw_Data!T9 -> Closed
A10: =Raw_Data!A10 -> EMP009 | B10: =Raw_Data!B10 -> Arjun Nair | C10: =Raw_Data!C10 -> Sales | D10: =Raw_Data!D10 -> Sales Executive | E10: =Raw_Data!E10 -> Kolkata | F10: =Raw_Data!F10 -> Sourav Das | G10: =DATE(VALUE(RIGHT(Raw_Data!G10,4)),VALUE(MID(Raw_Data!G10,4,2)),VALUE(LEFT(Raw_Data!G10,2))) -> 46113 | H10: =TEXT(G10,"mmm-yyyy") -> Apr-2026 | I10: =TEXT(G10,"ddd") -> Wed | J10: =Raw_Data!H10 -> Present | K10: =IF(Raw_Data!I10="","",TIMEVALUE(Raw_Data!I10)) -> 0.37916667 | L10: =IF(Raw_Data!J10="","",TIMEVALUE(Raw_Data!J10)) -> 0.74583333 | M10: =Raw_Data!K10 -> 8.81 | N10: =Raw_Data!L10 -> 17 | O10: =Raw_Data!M10 -> 12 | P10: =N10-O10 -> 5 | Q10: =Raw_Data!O10 -> 17 | R10: =IFERROR(O10/N10*100,0) -> 70.588235 | S10: =Raw_Data!Q10 -> 70.6 | T10: =Raw_Data!R10 -> 0.81 | U10: =Raw_Data!S10 -> Medium | V10: =Raw_Data!T10 -> Pending
A11: =Raw_Data!A11 -> EMP010 | B11: =Raw_Data!B11 -> Meera Kapoor | C11: =Raw_Data!C11 -> Sales | D11: =Raw_Data!D11 -> Sales Executive | E11: =Raw_Data!E11 -> Kolkata | F11: =Raw_Data!F11 -> Sourav Das | G11: =DATE(VALUE(RIGHT(Raw_Data!G11,4)),VALUE(MID(Raw_Data!G11,4,2)),VALUE(LEFT(Raw_Data!G11,2))) -> 46113 | H11: =TEXT(G11,"mmm-yyyy") -> Apr-2026 | I11: =TEXT(G11,"ddd") -> Wed | J11: =Raw_Data!H11 -> Present | K11: =IF(Raw_Data!I11="","",TIMEVALUE(Raw_Data!I11)) -> 0.37847222 | L11: =IF(Raw_Data!J11="","",TIMEVALUE(Raw_Data!J11)) -> 0.72430556 | M11: =Raw_Data!K11 -> 8.31 | N11: =Raw_Data!L11 -> 12 | O11: =Raw_Data!M11 -> 9 | P11: =N11-O11 -> 3 | Q11: =Raw_Data!O11 -> 12 | R11: =IFERROR(O11/N11*100,0) -> 75 | S11: =Raw_Data!Q11 -> 75 | T11: =Raw_Data!R11 -> 0.31 | U11: =Raw_Data!S11 -> High | V11: =Raw_Data!T11 -> In Progress
A12: =Raw_Data!A12 -> EMP011 | B12: =Raw_Data!B12 -> Karan Malhotra | C12: =Raw_Data!C12 -> Sales | D12: =Raw_Data!D12 -> Senior Executive | E12: =Raw_Data!E12 -> Kolkata | F12: =Raw_Data!F12 -> Sourav Das | G12: =DATE(VALUE(RIGHT(Raw_Data!G12,4)),VALUE(MID(Raw_Data!G12,4,2)),VALUE(LEFT(Raw_Data!G12,2))) -> 46113 | H12: =TEXT(G12,"mmm-yyyy") -> Apr-2026 | I12: =TEXT(G12,"ddd") -> Wed | J12: =Raw_Data!H12 -> Present | K12: =IF(Raw_Data!I12="","",TIMEVALUE(Raw_Data!I12)) -> 0.38194444 | L12: =IF(Raw_Data!J12="","",TIMEVALUE(Raw_Data!J12)) -> 0.76597222 | M12: =Raw_Data!K12 -> 9.22 | N12: =Raw_Data!L12 -> 20 | O12: =Raw_Data!M12 -> 14 | P12: =N12-O12 -> 6 | Q12: =Raw_Data!O12 -> 20 | R12: =IFERROR(O12/N12*100,0) -> 70 | S12: =Raw_Data!Q12 -> 70 | T12: =Raw_Data!R12 -> 1.22 | U12: =Raw_Data!S12 -> Low | V12: =Raw_Data!T12 -> Pending
A13: =Raw_Data!A13 -> EMP012 | B13: =Raw_Data!B13 -> Tanya Bose | C13: =Raw_Data!C13 -> HR | D13: =Raw_Data!D13 -> HR Executive | E13: =Raw_Data!E13 -> Kolkata | F13: =Raw_Data!F13 -> Ritu Ghosh | G13: =DATE(VALUE(RIGHT(Raw_Data!G13,4)),VALUE(MID(Raw_Data!G13,4,2)),VALUE(LEFT(Raw_Data!G13,2))) -> 46113 | H13: =TEXT(G13,"mmm-yyyy") -> Apr-2026 | I13: =TEXT(G13,"ddd") -> Wed | J13: =Raw_Data!H13 -> Present | K13: =IF(Raw_Data!I13="","",TIMEVALUE(Raw_Data!I13)) -> 0.3875 | L13: =IF(Raw_Data!J13="","",TIMEVALUE(Raw_Data!J13)) -> 0.775 | M13: =Raw_Data!K13 -> 9.3 | N13: =Raw_Data!L13 -> 8 | O13: =Raw_Data!M13 -> 6 | P13: =N13-O13 -> 2 | Q13: =Raw_Data!O13 -> 8 | R13: =IFERROR(O13/N13*100,0) -> 75 | S13: =Raw_Data!Q13 -> 75 | T13: =Raw_Data!R13 -> 1.3 | U13: =Raw_Data!S13 -> Medium | V13: =Raw_Data!T13 -> In Progress
... A2881: =Raw_Data!A2881 -> EMP020 | B2881: =Raw_Data!B2881 -> Riya Chatterjee | C2881: =Raw_Data!C2881 -> Customer Support | D2881: =Raw_Data!D2881 -> Support Executive | E2881: =Raw_Data!E2881 -> Durgapur | F2881: =Raw_Data!F2881 -> Ritu Ghosh | G2881: =DATE(VALUE(RIGHT(Raw_Data!G2881,4)),VALUE(MID(Raw_Data!G2881,4,2)),VALUE(LEFT(Raw_Data!G2881,2))) -> 46280 | H2881: =TEXT(G2881,"mmm-yyyy") -> Sep-2026 | I2881: =TEXT(G2881,"ddd") -> Tue | J2881: =Raw_Data!H2881 -> Present | K2881: =IF(Raw_Data!I2881="","",TIMEVALUE(Raw_Data!I2881)) -> 0.43055556 | L2881: =IF(Raw_Data!J2881="","",TIMEVALUE(Raw_Data!J2881)) -> 0.77013889 | M2881: =Raw_Data!K2881 -> 8.16 | N2881: =Raw_Data!L2881 -> 32 | O2881: =Raw_Data!M2881 -> 26 | P2881: =N2881-O2881 -> 6 | Q2881: =Raw_Data!O2881 -> 32 | R2881: =IFERROR(O2881/N2881*100,0) -> 81.25 | S2881: =Raw_Data!Q2881 -> 81.2 | T2881: =Raw_Data!R2881 -> 0.16 | U2881: =Raw_Data!S2881 -> Medium | V2881: =Raw_Data!T2881 -> Pending

Sheet Tables_and_Charts
A1: MIS Summary Tables & Charts
A2: All figures are formula-driven (SUMIFS / AVERAGEIFS / COUNTIFS) from Cleaned_Data
A4: TABLE 1: DEPARTMENT-WISE SUMMARY
A5: Department | B5: Records | C5: Avg Working Hrs | D5: Avg Achievement % | E5: Total Tasks Completed | F5: Attendance Rate %
A6: Operations | B6: =COUNTIF(Cleaned_Data!C2:C2881,A6) -> 1008 | C6: =ROUND(AVERAGEIF(Cleaned_Data!C2:C2881,A6,Cleaned_Data!M2:M2881),2) -> 8.09 | D6: =ROUND(AVERAGEIF(Cleaned_Data!C2:C2881,A6,Cleaned_Data!R2:R2881),1) -> 83.8 | E6: =SUMIF(Cleaned_Data!C2:C2881,A6,Cleaned_Data!O2:O2881) -> 19776 | F6: =ROUND((COUNTIFS(Cleaned_Data!C2:C2881,A6,Cleaned_Data!J2:J2881,"Present")+COUNTIFS(Cleaned_Data!C2:C2881,A6,Cleaned_Data!J2:J2881,"Late")+COUNTIFS(Cleaned_Data!C2:C2881,A6,Cleaned_Data!J2:J2881,"Half Day"))/B6*100,1) -> 97.1
A7: Finance | B7: =COUNTIF(Cleaned_Data!C2:C2881,A7) -> 576 | C7: =ROUND(AVERAGEIF(Cleaned_Data!C2:C2881,A7,Cleaned_Data!M2:M2881),2) -> 8.12 | D7: =ROUND(AVERAGEIF(Cleaned_Data!C2:C2881,A7,Cleaned_Data!R2:R2881),1) -> 82.6 | E7: =SUMIF(Cleaned_Data!C2:C2881,A7,Cleaned_Data!O2:O2881) -> 7325 | F7: =ROUND((COUNTIFS(Cleaned_Data!C2:C2881,A7,Cleaned_Data!J2:J2881,"Present")+COUNTIFS(Cleaned_Data!C2:C2881,A7,Cleaned_Data!J2:J2881,"Late")+COUNTIFS(Cleaned_Data!C2:C2881,A7,Cleaned_Data!J2:J2881,"Half Day"))/B7*100,1) -> 97
A8: Sales | B8: =COUNTIF(Cleaned_Data!C2:C2881,A8) -> 576 | C8: =ROUND(AVERAGEIF(Cleaned_Data!C2:C2881,A8,Cleaned_Data!M2:M2881),2) -> 7.98 | D8: =ROUND(AVERAGEIF(Cleaned_Data!C2:C2881,A8,Cleaned_Data!R2:R2881),1) -> 82.3 | E8: =SUMIF(Cleaned_Data!C2:C2881,A8,Cleaned_Data!O2:O2881) -> 9076 | F8: =ROUND((COUNTIFS(Cleaned_Data!C2:C2881,A8,Cleaned_Data!J2:J2881,"Present")+COUNTIFS(Cleaned_Data!C2:C2881,A8,Cleaned_Data!J2:J2881,"Late")+COUNTIFS(Cleaned_Data!C2:C2881,A8,Cleaned_Data!J2:J2881,"Half Day"))/B8*100,1) -> 96.2
A9: HR | B9: =COUNTIF(Cleaned_Data!C2:C2881,A9) -> 144 | C9: =ROUND(AVERAGEIF(Cleaned_Data!C2:C2881,A9,Cleaned_Data!M2:M2881),2) -> 8.03 | D9: =ROUND(AVERAGEIF(Cleaned_Data!C2:C2881,A9,Cleaned_Data!R2:R2881),1) -> 78.1 | E9: =SUMIF(Cleaned_Data!C2:C2881,A9,Cleaned_Data!O2:O2881) -> 1321 | F9: =ROUND((COUNTIFS(Cleaned_Data!C2:C2881,A9,Cleaned_Data!J2:J2881,"Present")+COUNTIFS(Cleaned_Data!C2:C2881,A9,Cleaned_Data!J2:J2881,"Late")+COUNTIFS(Cleaned_Data!C2:C2881,A9,Cleaned_Data!J2:J2881,"Half Day"))/B9*100,1) -> 95.1
A10: Customer Support | B10: =COUNTIF(Cleaned_Data!C2:C2881,A10) -> 576 | C10: =ROUND(AVERAGEIF(Cleaned_Data!C2:C2881,A10,Cleaned_Data!M2:M2881),2) -> 8.14 | D10: =ROUND(AVERAGEIF(Cleaned_Data!C2:C2881,A10,Cleaned_Data!R2:R2881),1) -> 83.5 | E10: =SUMIF(Cleaned_Data!C2:C2881,A10,Cleaned_Data!O2:O2881) -> 13154 | F10: =ROUND((COUNTIFS(Cleaned_Data!C2:C2881,A10,Cleaned_Data!J2:J2881,"Present")+COUNTIFS(Cleaned_Data!C2:C2881,A10,Cleaned_Data!J2:J2881,"Late")+COUNTIFS(Cleaned_Data!C2:C2881,A10,Cleaned_Data!J2:J2881,"Half Day"))/B10*100,1) -> 97
A12: TABLE 2: ATTENDANCE STATUS DISTRIBUTION
A13: Attendance Status | B13: Count | C13: % of Total
A14: Present | B14: =COUNTIF(Cleaned_Data!J2:J2881,A14) -> 2627 | C14: =ROUND(B14/2880*100,1) -> 91.2
A15: Late | B15: =COUNTIF(Cleaned_Data!J2:J2881,A15) -> 120 | C15: =ROUND(B15/2880*100,1) -> 4.2
A16: Half Day | B16: =COUNTIF(Cleaned_Data!J2:J2881,A16) -> 41 | C16: =ROUND(B16/2880*100,1) -> 1.4
A17: Leave | B17: =COUNTIF(Cleaned_Data!J2:J2881,A17) -> 79 | C17: =ROUND(B17/2880*100,1) -> 2.7
A18: Absent | B18: =COUNTIF(Cleaned_Data!J2:J2881,A18) -> 13 | C18: =ROUND(B18/2880*100,1) -> 0.5
A20: TABLE 3: MONTHLY TREND (APR–SEP 2026)
A21: Month | B21: Avg Achievement % | C21: Avg Working Hrs | D21: Records
A22: Apr-2026 | B22: =ROUND(AVERAGEIF(Cleaned_Data!H2:H2881,A22,Cleaned_Data!R2:R2881),1) -> 83.7 | C22: =ROUND(AVERAGEIF(Cleaned_Data!H2:H2881,A22,Cleaned_Data!M2:M2881),2) -> 8.09 | D22: =COUNTIF(Cleaned_Data!H2:H2881,A22) -> 520
A23: May-2026 | B23: =ROUND(AVERAGEIF(Cleaned_Data!H2:H2881,A23,Cleaned_Data!R2:R2881),1) -> 83 | C23: =ROUND(AVERAGEIF(Cleaned_Data!H2:H2881,A23,Cleaned_Data!M2:M2881),2) -> 8.14 | D23: =COUNTIF(Cleaned_Data!H2:H2881,A23) -> 520
A24: Jun-2026 | B24: =ROUND(AVERAGEIF(Cleaned_Data!H2:H2881,A24,Cleaned_Data!R2:R2881),1) -> 82.4 | C24: =ROUND(AVERAGEIF(Cleaned_Data!H2:H2881,A24,Cleaned_Data!M2:M2881),2) -> 8.09 | D24: =COUNTIF(Cleaned_Data!H2:H2881,A24) -> 520
A25: Jul-2026 | B25: =ROUND(AVERAGEIF(Cleaned_Data!H2:H2881,A25,Cleaned_Data!R2:R2881),1) -> 82.6 | C25: =ROUND(AVERAGEIF(Cleaned_Data!H2:H2881,A25,Cleaned_Data!M2:M2881),2) -> 8.08 | D25: =COUNTIF(Cleaned_Data!H2:H2881,A25) -> 540
A26: Aug-2026 | B26: =ROUND(AVERAGEIF(Cleaned_Data!H2:H2881,A26,Cleaned_Data!R2:R2881),1) -> 82.7 | C26: =ROUND(AVERAGEIF(Cleaned_Data!H2:H2881,A26,Cleaned_Data!M2:M2881),2) -> 8.06 | D26: =COUNTIF(Cleaned_Data!H2:H2881,A26) -> 520
A27: Sep-2026 | B27: =ROUND(AVERAGEIF(Cleaned_Data!H2:H2881,A27,Cleaned_Data!R2:R2881),1) -> 83.1 | C27: =ROUND(AVERAGEIF(Cleaned_Data!H2:H2881,A27,Cleaned_Data!M2:M2881),2) -> 7.97 | D27: =COUNTIF(Cleaned_Data!H2:H2881,A27) -> 260
A29: TABLE 4: LOCATION-WISE SUMMARY
A30: Location | B30: Records | C30: Avg Achievement % | D30: Avg Working Hrs | E30: Total Overtime Hrs
A31: Kolkata | B31: =COUNTIF(Cleaned_Data!E2:E2881,A31) -> 2160 | C31: =ROUND(AVERAGEIF(Cleaned_Data!E2:E2881,A31,Cleaned_Data!R2:R2881),1) -> 82.7 | D31: =ROUND(AVERAGEIF(Cleaned_Data!E2:E2881,A31,Cleaned_Data!M2:M2881),2) -> 8.06 | E31: =ROUND(SUMIF(Cleaned_Data!E2:E2881,A31,Cleaned_Data!T2:T2881),1) -> 1111.1
A32: Durgapur | B32: =COUNTIF(Cleaned_Data!E2:E2881,A32) -> 720 | C32: =ROUND(AVERAGEIF(Cleaned_Data!E2:E2881,A32,Cleaned_Data!R2:R2881),1) -> 83.4 | D32: =ROUND(AVERAGEIF(Cleaned_Data!E2:E2881,A32,Cleaned_Data!M2:M2881),2) -> 8.15 | E32: =ROUND(SUMIF(Cleaned_Data!E2:E2881,A32,Cleaned_Data!T2:T2881),1) -> 369.5
A34: TABLE 5: DESIGNATION-WISE AVERAGE ACHIEVEMENT %
A35: Designation | B35: Records | C35: Avg Achievement %
A36: MIS Executive | B36: =COUNTIF(Cleaned_Data!D2:D2881,A36) -> 144 | C36: =ROUND(AVERAGEIF(Cleaned_Data!D2:D2881,A36,Cleaned_Data!R2:R2881),1) -> 84.3
A37: Process Executive | B37: =COUNTIF(Cleaned_Data!D2:D2881,A37) -> 720 | C37: =ROUND(AVERAGEIF(Cleaned_Data!D2:D2881,A37,Cleaned_Data!R2:R2881),1) -> 84.2
A38: Senior Executive | B38: =COUNTIF(Cleaned_Data!D2:D2881,A38) -> 432 | C38: =ROUND(AVERAGEIF(Cleaned_Data!D2:D2881,A38,Cleaned_Data!R2:R2881),1) -> 82.6
A39: Finance Executive | B39: =COUNTIF(Cleaned_Data!D2:D2881,A39) -> 432 | C39: =ROUND(AVERAGEIF(Cleaned_Data!D2:D2881,A39,Cleaned_Data!R2:R2881),1) -> 81.9
A40: Accounts Executive | B40: =COUNTIF(Cleaned_Data!D2:D2881,A40) -> 144 | C40: =ROUND(AVERAGEIF(Cleaned_Data!D2:D2881,A40,Cleaned_Data!R2:R2881),1) -> 84.9
A41: Sales Executive | B41: =COUNTIF(Cleaned_Data!D2:D2881,A41) -> 432 | C41: =ROUND(AVERAGEIF(Cleaned_Data!D2:D2881,A41,Cleaned_Data!R2:R2881),1) -> 82.5
A42: HR Executive | B42: =COUNTIF(Cleaned_Data!D2:D2881,A42) -> 144 | C42: =ROUND(AVERAGEIF(Cleaned_Data!D2:D2881,A42,Cleaned_Data!R2:R2881),1) -> 78.1
A43: Support Executive | B43: =COUNTIF(Cleaned_Data!D2:D2881,A43) -> 432 | C43: =ROUND(AVERAGEIF(Cleaned_Data!D2:D2881,A43,Cleaned_Data!R2:R2881),1) -> 83.1
A45: TABLE 6: EMPLOYEE-WISE PERFORMANCE SUMMARY (all 20 employees)
A46: Employee ID | B46: Employee Name | C46: Department | D46: Avg Achievement % | E46: Avg Working Hrs | F46: Attendance Rate %
...

Sheet Dashboard
A1: EMPLOYEE PRODUCTIVITY — MIS DASHBOARD
A3: Period: Apr–Sep 2026 | 20 Employees | 5 Departments | 2 Locations (Kolkata, Durgapur) | Source: Cleaned_Data (2,880 records)
A5: TOTAL EMPLOYEES | D5: TOTAL RECORDS | G5: AVG ACHIEVEMENT % | J5: ATTENDANCE RATE %
A6: =SUMPRODUCT(1/COUNTIF(Cleaned_Data!A2:A2881,Cleaned_Data!A2:A2881)) -> 20 | D6: =COUNTA(Cleaned_Data!A2:A2881) -> 2880 | G6: =ROUND(AVERAGE(Cleaned_Data!R2:R2881),1) -> 82.9 | J6: =ROUND((COUNTIF(Cleaned_Data!J2:J2881,"Present")+COUNTIF(Cleaned_Data!J2:J2881,"Late")+COUNTIF(Cleaned_Data!J2:J2881,"Half Day"))/2880*100,1) -> 96.8
A9: TOTAL TASKS COMPLETED | D9: TOTAL PENDING TASKS | G9: AVG WORKING HRS/DAY | J9: TOTAL OVERTIME HRS
A10: =SUM(Cleaned_Data!O2:O2881) -> 50652 | D10: =SUM(Cleaned_Data!P2:P2881) -> 8227 | G10: =ROUND(AVERAGE(Cleaned_Data!M2:M2881),2) -> 8.08 | J10: =ROUND(SUM(Cleaned_Data!T2:T2881),1) -> 1480.6
A13: KEY VISUALS
A53: MIS INSIGHTS SUMMARY
A54: • Overall attendance rate is strong (~97%); HR department shows the lowest average achievement (78.1%) among all departments — worth a closer review.
A55: • Customer Support and Operations lead on average achievement %, both above the company-wide average.
A56: • Only Low-priority cases are ever marked “Closed” in this period — Critical/High/Medium priority cases stay in Progress/Pending/Backlog, a potential process bottleneck.
A57: • Durgapur location tracks close to Kolkata on achievement %, showing consistent performance across sites.
A58: • Achievement % and Productivity % columns were found to be identical in the source data — flagged during cleaning as a redundant field.
